<?xml version="1.0"?>
<robot name="My_Robot">

  <link name="base_link">
    <visual>
      <geometry>
        <box size="0.6 0.3 0.3"/>
      </geometry>
      <material name="silver">
        <color rgba="0.75 0.75 0.75 1"/>
      </material>
    </visual>
    <collision>
      <geometry>
        <box size="0.6 0.3 0.3"/>
      </geometry>
    </collision>
    <inertial>
      <mass value="1.0"/>
      <inertia ixx="0.015" iyy="0.0375" izz="0.0375"
               ixy="0" ixz="0" iyz="0"/>
    </inertial>
  </link>


  <link name="fcu">
    <!-- FCU frame (mavros uses this link for most topics) -->
    <visual>
      <geometry>
        <!-- Pixhawk -->
        <box size=".085 .052 .02" />
      </geometry>
      <material name="dark-grey" />
    </visual>
  </link>
  <joint name="base_to_fcu" type="fixed">
    <parent link="base_link" />
    <child link="fcu" />
    <!-- FCU located on top of robot
         -->
    <origin xyz="0 0 0.26" rpy="0 1.57 0" />
  </joint>


  <link name="front_caster">
    <visual>
      <geometry>
        <box size="0.1 0.1 0.3"/>
      </geometry>
      <material name="silver"/>
    </visual>
    <inertial>
      <mass value="0.1"/>
      <inertia ixx="0.00083" iyy="0.00083" izz="0.000167"
               ixy="0" ixz="0" iyz="0"/>
    </inertial>
  </link>

  <joint name="front_caster_joint" type="continuous">
    <axis xyz="0 0 1"/>
    <parent link="base_link"/>
    <child link="front_caster"/>
    <origin rpy="0 0 0" xyz="0.3 0 0"/>
  </joint>

  <link name="front_wheel">
    <visual>
      <geometry>
        <cylinder length="0.05" radius="0.035"/>
      </geometry>
      <material name="black"/>
    </visual>
    <collision>
       <origin xyz="0 0 0" rpy="0 0 0 " />
       <geometry>
         <cylinder length="0.05" radius="0.035" />
       </geometry>
    </collision>
    <inertial>
      <mass value="0.1"/>
      <inertia ixx="5.1458e-5" iyy="5.1458e-5" izz="6.125e-5"
               ixy="0" ixz="0" iyz="0"/>
    </inertial>
  </link>

  <joint name="front_wheel_joint" type="continuous">
    <axis xyz="0 0 1"/>
    <parent link="front_caster"/>
    <child link="front_wheel"/>
    <origin rpy="-1.5708 0 0" xyz="0.05 0 -.15"/>
  </joint>

  <link name="right_wheel">
    <visual>
      <geometry>
        <cylinder length="0.05" radius="0.035"/>
      </geometry>
      <material name="black">
        <color rgba="0 0 0 1"/>
      </material>
    </visual>
    <collision>
      <origin rpy="0 0 0" xyz="0 0 0"/>
       <geometry>
         <cylinder length="0.05" radius="0.035" />
       </geometry>
    </collision>
    <inertial>
      <mass value="0.1"/>
      <inertia ixx="5.1458e-5" iyy="5.1458e-5" izz="6.125e-5"
               ixy="0" ixz="0" iyz="0"/>
    </inertial>
  </link>
    <joint name="right_wheel_joint" type="continuous">
      <axis xyz="0 0 1"/>
      <parent link="base_link"/>
      <child link="right_wheel"/>
      <origin rpy="-1.5708 0 0" xyz="-0.2825 -0.125 -.15"/>
    </joint>
  <link name="left_wheel">
    <visual>
      <geometry>
        <cylinder length="0.05" radius="0.035"/>
      </geometry>
      <material name="black"/>
    </visual>
    <collision>
      <origin rpy="0 0 0" xyz="0 0 0"/>
       <geometry>
         <cylinder length="0.05" radius="0.035" />
       </geometry>
    </collision>
    <inertial>
      <mass value="0.1"/>
      <inertia ixx="5.1458e-5" iyy="5.1458e-5" izz="6.125e-5"
               ixy="0" ixz="0" iyz="0"/>
    </inertial>
  </link>
  <joint name="left_wheel_joint" type="continuous">
    <axis xyz="0 0 1"/>
    <parent link="base_link"/>
    <child link="left_wheel"/>
    <origin rpy="-1.5708 0 0" xyz="-0.2825 0.125 -.15"/>
  </joint>

  <link name="hokuyo_link">
    <collision>
      <origin xyz="0 0 0" rpy="0 0 0"/>
      <geometry>
        <box size="0.1 0.1 0.1"/>
      </geometry>
    </collision>
    <visual>
      <origin xyz="0 0 0" rpy="0 0 0"/>
      <geometry>
        <box size="0.1 0.1 0.1"/>
      </geometry>
    </visual>
    <inertial>
      <mass value="1e-5" />
      <origin xyz="0 0 0" rpy="0 0 0"/>
      <inertia ixx="1e-6" ixy="0" ixz="0" iyy="1e-6" iyz="0" izz="1e-6" />
    </inertial>
  </link>
  <joint name="hokuyo_joint" type="fixed">
    <axis xyz="0 1 0" />
    <origin xyz="0 0 0.2" rpy="0 0 0"/>
    <parent link="base_link"/>
    <child link="hokuyo_link"/>
  </joint>


  <gazebo>
    <plugin name="differential_drive_controller"
            filename="libgazebo_ros_diff_drive.so">
      <leftJoint>left_wheel_joint</leftJoint>
      <rightJoint>right_wheel_joint</rightJoint>
      <robotBaseFrame>base_link</robotBaseFrame>
      <wheelSeparation>0.25</wheelSeparation>
      <wheelDiameter>0.07</wheelDiameter>
      <publishWheelJointState>true</publishWheelJointState>
    </plugin>

    <plugin name="joint_state_publisher"
            filename="libgazebo_ros_joint_state_publisher.so">
            <jointName>front_caster_joint, front_wheel_joint</jointName>
    </plugin>
    <plugin name='rotors_gazebo_imu_plugin' filename='librotors_gazebo_imu_plugin.so'>
      <robotNamespace></robotNamespace>
      <linkName>rover/imu_link</linkName>
      <imuTopic>/imu</imuTopic>
      <gyroscopeNoiseDensity>0.0003394</gyroscopeNoiseDensity>
      <gyroscopeRandomWalk>3.8785e-05</gyroscopeRandomWalk>
      <gyroscopeBiasCorrelationTime>1000.0</gyroscopeBiasCorrelationTime>
      <gyroscopeTurnOnBiasSigma>0.0087</gyroscopeTurnOnBiasSigma>
      <accelerometerNoiseDensity>0.004</accelerometerNoiseDensity>
      <accelerometerRandomWalk>0.006</accelerometerRandomWalk>
      <accelerometerBiasCorrelationTime>300.0</accelerometerBiasCorrelationTime>
      <accelerometerTurnOnBiasSigma>0.196</accelerometerTurnOnBiasSigma>
    </plugin>

    <plugin name="gps_plugin" filename="libgazebo_gps_plugin.so">
    	<robotNamespace></robotNamespace>
    	<gpsNoise>true</gpsNoise>
    </plugin>

    <plugin name='mavlink_interface' filename='librotors_gazebo_mavlink_interface.so'>
      <robotNamespace></robotNamespace>
      <imuSubTopic>/imu</imuSubTopic>
      <gpsSubTopic>/gps</gpsSubTopic>
      <mavlink_addr>INADDR_ANY</mavlink_addr>
      <mavlink_udp_port>14560</mavlink_udp_port>
      <serialEnabled>false</serialEnabled>
      <serialDevice>/dev/ttyACM0</serialDevice>
      <baudRate>921600</baudRate>
      <qgc_addr>INADDR_ANY</qgc_addr>
      <qgc_udp_port>14550</qgc_udp_port>
      <hil_mode>false</hil_mode>
      <hil_state_level>false</hil_state_level>
      <motorSpeedCommandPubTopic>/gazebo/command/motor_speed</motorSpeedCommandPubTopic>
      <control_channels>
        <!--
        <channel name="front_left_wheel_drive">
          <input_index>3</input_index>
          <input_offset>0</input_offset>
          <input_scaling>10</input_scaling>
          <zero_position_disarmed>0</zero_position_disarmed>
          <zero_position_armed>0</zero_position_armed>
          <joint_control_type>velocity_kinematic</joint_control_type>
          <joint_name>front_left_wheel_joint</joint_name>
        </channel>
        <channel name="front_right_wheel_drive">
          <input_index>4</input_index>
          <input_offset>0</input_offset>
          <input_scaling>10</input_scaling>
          <zero_position_disarmed>0</zero_position_disarmed>
          <zero_position_armed>0</zero_position_armed>
          <joint_control_type>velocity_kinematic</joint_control_type>
          <joint_name>front_right_wheel_joint</joint_name>
        </channel>
      -->
        <channel name="rear_left_wheel_drive">
          <input_index>5</input_index>
          <input_offset>0</input_offset>
          <input_scaling>40</input_scaling>
          <zero_position_disarmed>0</zero_position_disarmed>
          <zero_position_armed>0</zero_position_armed>
          <joint_control_type>velocity</joint_control_type>
          <joint_name>rear_left_wheel_joint</joint_name>
          <joint_control_pid>
            <p>50</p>
            <i>20</i>
            <d>2</d>
            <iMax>800</iMax>
            <iMin>-800</iMin>
            <cmdMax>1200</cmdMax>
            <cmdMin>-1200</cmdMin>
          </joint_control_pid>
        </channel>
        <channel name="rear_right_wheel_drive">
          <input_index>6</input_index>
          <input_offset>0</input_offset>
          <input_scaling>40</input_scaling>
          <zero_position_disarmed>0</zero_position_disarmed>
          <zero_position_armed>0</zero_position_armed>
          <joint_control_type>velocity</joint_control_type>
          <joint_name>rear_right_wheel_joint</joint_name>
          <joint_control_pid>
            <p>50</p>
            <i>20</i>
            <d>2</d>
            <iMax>800</iMax>
            <iMin>-800</iMin>
            <cmdMax>1200</cmdMax>
            <cmdMin>-1200</cmdMin>
          </joint_control_pid>
        </channel>
        <channel name="left_wheel_steering">
          <input_index>0</input_index>
          <input_offset>0</input_offset>
          <input_scaling>-0.9</input_scaling>
          <zero_position_disarmed>0</zero_position_disarmed>
          <zero_position_armed>0</zero_position_armed>
          <joint_control_type>position</joint_control_type>
          <joint_name>front_left_steering_joint</joint_name>
          <joint_control_pid>
            <p>80</p>
            <i>40</i>
            <d>0.1</d>
            <iMax>40</iMax>
            <iMin>-40</iMin>
            <cmdMax>80</cmdMax>
            <cmdMin>-80</cmdMin>
          </joint_control_pid>
        </channel>
        <channel name="right_wheel_steering">
          <input_index>1</input_index>
          <input_offset>0</input_offset>
          <input_scaling>-0.9</input_scaling>
          <zero_position_disarmed>0</zero_position_disarmed>
          <zero_position_armed>0</zero_position_armed>
          <joint_control_type>position</joint_control_type>
          <joint_name>front_right_steering_joint</joint_name>
          <joint_control_pid>
            <p>80</p>
            <i>40</i>
            <d>0.1</d>
            <iMax>40</iMax>
            <iMin>-40</iMin>
            <cmdMax>80</cmdMax>
            <cmdMin>-80</cmdMin>
          </joint_control_pid>
        </channel>
      </control_channels>
    </plugin>
  </gazebo>


  <gazebo reference="hokuyo_link">
    <material>Gazebo/Blue</material>
    <turnGravityOff>false</turnGravityOff>
    <sensor type="ray" name="head_hokuyo_sensor">
      <pose>${hokuyo_size/2} 0 0 0 0 0</pose>
      <visualize>false</visualize>
      <update_rate>40</update_rate>
      <ray>
        <scan>
          <horizontal>
            <samples>720</samples>
            <resolution>1</resolution>
            <min_angle>-1.570796</min_angle>
            <max_angle>1.570796</max_angle>
          </horizontal>
        </scan>
        <range>
          <min>0.10</min>
          <max>10.0</max>
          <resolution>0.001</resolution>
        </range>
      </ray>
      <plugin name="gazebo_ros_head_hokuyo_controller" filename="libgazebo_ros_laser.so">
        <topicName>/scan</topicName>
        <frameName>hokuyo_link</frameName>
      </plugin>
    </sensor>
  </gazebo>
</robot>
