<?xml version="1.0"?>
<robot name="My_Robot">

  <link name="base_link">
    <visual>
      <geometry>
        <box size="0.6 0.3 0.3"/>
      </geometry>
      <material name="silver">
        <color rgba="0.75 0.75 0.75 1"/>
      </material>
    </visual>
    <collision>
      <geometry>
        <box size="0.6 0.3 0.3"/>
      </geometry>
    </collision>
    <inertial>
      <mass value="1.0"/>
      <inertia ixx="0.015" iyy="0.0375" izz="0.0375"
               ixy="0" ixz="0" iyz="0"/>
    </inertial>
  </link>


  <link name="fcu">
    <!-- FCU frame (mavros uses this link for most topics) -->
    <visual>
      <geometry>
        <!-- Pixhawk -->
        <box size=".085 .052 .02" />
      </geometry>
      <material name="dark-grey" />
    </visual>
  </link>
  <joint name="base_to_fcu" type="fixed">
    <parent link="base_link" />
    <child link="fcu" />
    <!-- FCU located on top of robot
         -->
    <origin xyz="0 0 0.26" rpy="0 1.57 0" />
  </joint>


  <link name="front_caster">
    <visual>
      <geometry>
        <box size="0.1 0.1 0.3"/>
      </geometry>
      <material name="silver"/>
    </visual>
    <inertial>
      <mass value="0.1"/>
      <inertia ixx="0.00083" iyy="0.00083" izz="0.000167"
               ixy="0" ixz="0" iyz="0"/>
    </inertial>
  </link>

  <joint name="front_caster_joint" type="continuous">
    <axis xyz="0 0 1"/>
    <parent link="base_link"/>
    <child link="front_caster"/>
    <origin rpy="0 0 0" xyz="0.3 0 0"/>
  </joint>

  <link name="front_wheel">
    <visual>
      <geometry>
        <cylinder length="0.05" radius="0.035"/>
      </geometry>
      <material name="black"/>
    </visual>
    <collision>
       <origin xyz="0 0 0" rpy="0 0 0 " />
       <geometry>
         <cylinder length="0.05" radius="0.035" />
       </geometry>
    </collision>
    <inertial>
      <mass value="0.1"/>
      <inertia ixx="5.1458e-5" iyy="5.1458e-5" izz="6.125e-5"
               ixy="0" ixz="0" iyz="0"/>
    </inertial>
  </link>

  <joint name="front_wheel_joint" type="continuous">
    <axis xyz="0 0 1"/>
    <parent link="front_caster"/>
    <child link="front_wheel"/>
    <origin rpy="-1.5708 0 0" xyz="0.05 0 -.15"/>
  </joint>

  <link name="right_wheel">
    <visual>
      <geometry>
        <cylinder length="0.05" radius="0.035"/>
      </geometry>
      <material name="black">
        <color rgba="0 0 0 1"/>
      </material>
    </visual>
    <collision>
      <origin rpy="0 0 0" xyz="0 0 0"/>
       <geometry>
         <cylinder length="0.05" radius="0.035" />
       </geometry>
    </collision>
    <inertial>
      <mass value="0.1"/>
      <inertia ixx="5.1458e-5" iyy="5.1458e-5" izz="6.125e-5"
               ixy="0" ixz="0" iyz="0"/>
    </inertial>
  </link>
  <joint name="right_wheel_joint" type="continuous">
    <axis xyz="0 0 1"/>
    <parent link="base_link"/>
    <child link="right_wheel"/>
    <origin rpy="-1.5708 0 0" xyz="-0.2825 -0.125 -.15"/>
  </joint>
  <link name="left_wheel">
    <visual>
      <geometry>
        <cylinder length="0.05" radius="0.035"/>
      </geometry>
      <material name="black"/>
    </visual>
    <collision>
      <origin rpy="0 0 0" xyz="0 0 0"/>
       <geometry>
         <cylinder length="0.05" radius="0.035" />
       </geometry>
    </collision>
    <inertial>
      <mass value="0.1"/>
      <inertia ixx="5.1458e-5" iyy="5.1458e-5" izz="6.125e-5"
               ixy="0" ixz="0" iyz="0"/>
    </inertial>
  </link>
  <joint name="left_wheel_joint" type="continuous">
    <axis xyz="0 0 1"/>
    <parent link="base_link"/>
    <child link="left_wheel"/>
    <origin rpy="-1.5708 0 0" xyz="-0.2825 0.125 -.15"/>
  </joint>

  <link name="hokuyo_link">
    <collision>
      <origin xyz="0 0 0" rpy="0 0 0"/>
      <geometry>
        <box size="0.1 0.1 0.1"/>
      </geometry>
    </collision>
    <visual>
      <origin xyz="0 0 0" rpy="0 0 0"/>
      <geometry>
        <box size="0.1 0.1 0.1"/>
      </geometry>
    </visual>
    <inertial>
      <mass value="1e-5" />
      <origin xyz="0 0 0" rpy="0 0 0"/>
      <inertia ixx="1e-6" ixy="0" ixz="0" iyy="1e-6" iyz="0" izz="1e-6" />
    </inertial>
  </link>
  <joint name="hokuyo_joint" type="fixed">
    <axis xyz="0 1 0" />
    <origin xyz="0 0 0.2" rpy="0 0 0"/>
    <parent link="base_link"/>
    <child link="hokuyo_link"/>
  </joint>


  <gazebo>
    <plugin name="differential_drive_controller"
            filename="libgazebo_ros_diff_drive.so">
    <leftJoint>left_wheel_joint</leftJoint>
    <rightJoint>right_wheel_joint</rightJoint>
    <robotBaseFrame>base_link</robotBaseFrame>
    <wheelSeparation>0.25</wheelSeparation>
    <wheelDiameter>0.07</wheelDiameter>
    <publishWheelJointState>true</publishWheelJointState>
    </plugin>

    <plugin name="joint_state_publisher"
            filename="libgazebo_ros_joint_state_publisher.so">
            <jointName>front_caster_joint, front_wheel_joint</jointName>
    </plugin>
  </gazebo>


  <gazebo reference="hokuyo_link">
    <material>Gazebo/Blue</material>
    <turnGravityOff>false</turnGravityOff>
    <sensor type="ray" name="head_hokuyo_sensor">
      <pose>20 0 0 0 0 0</pose>
      <visualize>false</visualize>
      <update_rate>40</update_rate>
      <ray>
        <scan>
          <horizontal>
            <samples>720</samples>
            <resolution>1</resolution>
            <min_angle>-1.570796</min_angle>
            <max_angle>1.570796</max_angle>
          </horizontal>
        </scan>
        <range>
          <min>0.10</min>
          <max>10.0</max>
          <resolution>0.001</resolution>
        </range>
      </ray>
      <plugin name="gazebo_ros_head_hokuyo_controller" filename="libgazebo_ros_laser.so">
        <topicName>/scan</topicName>
        <frameName>hokuyo_link</frameName>
      </plugin>
    </sensor>
  </gazebo>
</robot>
